Workbook

Sheet 4
A1: Изобразить вид кодовой последовательности передаваемого сообщения, приведенного в таблице, для нижеперечисленных кодов
A2: № | B2: Передаваемое сообщение | D2: 1 | E2: 2 | F2: 3 | G2: 4 | H2: 5 | I2: 6 | J2: 7 | K2: 8 | L2: 9
A3: 10 | B3: 000100100 | D3: 1. Потенциальный код без возвращения к нулю
D4: =MID($B$3,D$2,1) -> 0 | E4: =MID($B$3,E$2,1) -> 0 | F4: =MID($B$3,F$2,1) -> 0 | G4: =MID($B$3,G$2,1) -> 1 | H4: =MID($B$3,H$2,1) -> 0 | I4: =MID($B$3,I$2,1) -> 0 | J4: =MID($B$3,J$2,1) -> 1 | K4: =MID($B$3,K$2,1) -> 0 | L4: =MID($B$3,L$2,1) -> 0
B5: Всего 2 уровня потенциала
B9: Для кодирования 0 используется нулевой потенциал, а 1 кодируется либо положительным потенциалом, либо отрицательным, при этом потенциал каждой новой единицы противоположен потенциалу предыдущей | D9: 2. Метод биполярного кодирования с альтернативной инверсией
D10: =MID($B$3,D$2,1) -> 0 | E10: =MID($B$3,E$2,1) -> 0 | F10: =MID($B$3,F$2,1) -> 0 | G10: =MID($B$3,G$2,1) -> 1 | H10: =MID($B$3,H$2,1) -> 0 | I10: =MID($B$3,I$2,1) -> 0 | J10: =MID($B$3,J$2,1) -> 1 | K10: =MID($B$3,K$2,1) -> 0 | L10: =MID($B$3,L$2,1) -> 0
B17: При передаче 0 потенциал не меняется, при передаче 1 меняется на противоположный | D17: 3. Потенциальный код с инверсией при единице
D18: =MID($B$3,D$2,1) -> 0 | E18: =MID($B$3,E$2,1) -> 0 | F18: =MID($B$3,F$2,1) -> 0 | G18: =MID($B$3,G$2,1) -> 1 | H18: =MID($B$3,H$2,1) -> 0 | I18: =MID($B$3,I$2,1) -> 0 | J18: =MID($B$3,J$2,1) -> 1 | K18: =MID($B$3,K$2,1) -> 0 | L18: =MID($B$3,L$2,1) -> 0
D22: 4. Биполярный импульсный код
D23: =MID($B$3,D$2,1) -> 0 | F23: =MID($B$3,E$2,1) -> 0 | H23: =MID($B$3,F$2,1) -> 0 | J23: =MID($B$3,G$2,1) -> 1 | L23: =MID($B$3,H$2,1) -> 0 | N23: =MID($B$3,I$2,1) -> 0 | P23: =MID($B$3,J$2,1) -> 1 | R23: =MID($B$3,K$2,1) -> 0 | T23: =MID($B$3,L$2,1) -> 0
B28: Информация кодируется перепадами потенциала, происходящими в середине каждого такта. 1 кодируется перепадом от низкого уровня сигнала к высокому | D28: 5. Манчестерский код
D29: =MID($B$3,D$2,1) -> 0 | F29: =MID($B$3,E$2,1) -> 0 | H29: =MID($B$3,F$2,1) -> 0 | J29: =MID($B$3,G$2,1) -> 1 | L29: =MID($B$3,H$2,1) -> 0 | N29: =MID($B$3,I$2,1) -> 0 | P29: =MID($B$3,J$2,1) -> 1 | R29: =MID($B$3,K$2,1) -> 0 | T29: =MID($B$3,L$2,1) -> 0
B34: Каждые два бита (2В) передаются за один такт сигналом, имеющим четыре состояния (1Q). Паре бит 00 соответствует потенциал -2,5 В, паре бит 01 потенциал -0,833 В, паре 11 — потенциал +0,833 В, а паре 10 — потенциал +2,5 В | D34: 6. Потенциальный код 2В1Q
D35: =MID($B$3,D$2,1) -> 0 | E35: =MID($B$3,E$2,1) -> 0 | F35: =MID($B$3,F$2,1) -> 0 | G35: =MID($B$3,G$2,1) -> 1 | H35: =MID($B$3,H$2,1) -> 0 | I35: =MID($B$3,I$2,1) -> 0 | J35: =MID($B$3,J$2,1) -> 1 | K35: =MID($B$3,K$2,1) -> 0 | L35: =MID($B$3,L$2,1) -> 0 | M35: 0
C36: +3
C38: +1
C40: -1
C42: -3

Sheet 5
A1: Вариант 10, аддитивный скремблер | J1: сделать для самосинхронизирующегося
A6: Скремблирование | S6: Дескремблирование
A7: Сообщение a_k | D7: 0000100100 | G7: Отводы: | I7: 2, 6, 10 | K7: Начальная установка регистра 0101010101 | S7: Начальная установка: 0101010101
A8: k | B8: a_k | C8: s1 | D8: s2 | E8: s3 | F8: s4 | G8: s5 | H8: s6 | I8: s7 | J8: s8 | K8: s9 | L8: s10 | M8: xor | N8: b_k | S8: k | T8: b_k | U8: s1 | V8: s2 | W8: s3 | X8: s4 | Y8: s5 | Z8: s6 | AA8: s7 | AB8: s8 | AC8: s9 | AD8: s10 | AE8: p_k | AF8: a'_k | AG8: контроль
A9: 1 | B9: 0 | C9: 0 | D9: 1 | E9: 0 | F9: 1 | G9: 0 | H9: 1 | I9: 0 | J9: 1 | K9: 0 | L9: 1 | M9: =_xlfn.BITXOR(D9,_xlfn.BITXOR(H9,L9)) -> 1 | N9: =_xlfn.BITXOR(B9,M9) -> 1 | S9: 1 | T9: =N9 -> 1 | U9: 0 | V9: 1 | W9: 0 | X9: 1 | Y9: 0 | Z9: 1 | AA9: 0 | AB9: 1 | AC9: 0 | AD9: 1 | AE9: =_xlfn.BITXOR(V9,_xlfn.BITXOR(Z9,AD9)) -> 1 | AF9: =_xlfn.BITXOR(T9,AE9) -> 0 | AG9: =IF(AF9=B9,"совпадает","НЕ совпадает") -> совпадает
A10: 2 | B10: 0 | C10: =M9 -> 1 | D10: =C9 -> 0 | E10: =D9 -> 1 | F10: =E9 -> 0 | G10: =F9 -> 1 | H10: =G9 -> 0 | I10: =H9 -> 1 | J10: =I9 -> 0 | K10: =J9 -> 1 | L10: =K9 -> 0 | M10: =_xlfn.BITXOR(D10,_xlfn.BITXOR(H10,L10)) -> 0 | N10: =_xlfn.BITXOR(B10,M10) -> 0 | S10: 2 | T10: =N10 -> 0 | U10: =AE9 -> 1 | V10: =U9 -> 0 | W10: =V9 -> 1 | X10: =W9 -> 0 | Y10: =X9 -> 1 | Z10: =Y9 -> 0 | AA10: =Z9 -> 1 | AB10: =AA9 -> 0 | AC10: =AB9 -> 1 | AD10: =AC9 -> 0 | AE10: =_xlfn.BITXOR(V10,_xlfn.BITXOR(Z10,AD10)) -> 0 | AF10: =_xlfn.BITXOR(T10,AE10) -> 0 | AG10: =IF(AF10=B10,"совпадает","НЕ совпадает") -> совпадает
A11: 3 | B11: 0 | C11: =M10 -> 0 | D11: =C10 -> 1 | E11: =D10 -> 0 | F11: =E10 -> 1 | G11: =F10 -> 0 | H11: =G10 -> 1 | I11: =H10 -> 0 | J11: =I10 -> 1 | K11: =J10 -> 0 | L11: =K10 -> 1 | M11: =_xlfn.BITXOR(D11,_xlfn.BITXOR(H11,L11)) -> 1 | N11: =_xlfn.BITXOR(B11,M11) -> 1 | S11: 3 | T11: =N11 -> 1 | U11: =AE10 -> 0 | V11: =U10 -> 1 | W11: =V10 -> 0 | X11: =W10 -> 1 | Y11: =X10 -> 0 | Z11: =Y10 -> 1 | AA11: =Z10 -> 0 | AB11: =AA10 -> 1 | AC11: =AB10 -> 0 | AD11: =AC10 -> 1 | AE11: =_xlfn.BITXOR(V11,_xlfn.BITXOR(Z11,AD11)) -> 1 | AF11: =_xlfn.BITXOR(T11,AE11) -> 0 | AG11: =IF(AF11=B11,"совпадает","НЕ совпадает") -> совпадает
A12: 4 | B12: 0 | C12: =M11 -> 1 | D12: =C11 -> 0 | E12: =D11 -> 1 | F12: =E11 -> 0 | G12: =F11 -> 1 | H12: =G11 -> 0 | I12: =H11 -> 1 | J12: =I11 -> 0 | K12: =J11 -> 1 | L12: =K11 -> 0 | M12: =_xlfn.BITXOR(D12,_xlfn.BITXOR(H12,L12)) -> 0 | N12: =_xlfn.BITXOR(B12,M12) -> 0 | S12: 4 | T12: =N12 -> 0 | U12: =AE11 -> 1 | V12: =U11 -> 0 | W12: =V11 -> 1 | X12: =W11 -> 0 | Y12: =X11 -> 1 | Z12: =Y11 -> 0 | AA12: =Z11 -> 1 | AB12: =AA11 -> 0 | AC12: =AB11 -> 1 | AD12: =AC11 -> 0 | AE12: =_xlfn.BITXOR(V12,_xlfn.BITXOR(Z12,AD12)) -> 0 | AF12: =_xlfn.BITXOR(T12,AE12) -> 0 | AG12: =IF(AF12=B12,"совпадает","НЕ совпадает") -> совпадает
A13: 5 | B13: 1 | C13: =M12 -> 0 | D13: =C12 -> 1 | E13: =D12 -> 0 | F13: =E12 -> 1 | G13: =F12 -> 0 | H13: =G12 -> 1 | I13: =H12 -> 0 | J13: =I12 -> 1 | K13: =J12 -> 0 | L13: =K12 -> 1 | M13: =_xlfn.BITXOR(D13,_xlfn.BITXOR(H13,L13)) -> 1 | N13: =_xlfn.BITXOR(B13,M13) -> 0 | S13: 5 | T13: =N13 -> 0 | U13: =AE12 -> 0 | V13: =U12 -> 1 | W13: =V12 -> 0 | X13: =W12 -> 1 | Y13: =X12 -> 0 | Z13: =Y12 -> 1 | AA13: =Z12 -> 0 | AB13: =AA12 -> 1 | AC13: =AB12 -> 0 | AD13: =AC12 -> 1 | AE13: =_xlfn.BITXOR(V13,_xlfn.BITXOR(Z13,AD13)) -> 1 | AF13: =_xlfn.BITXOR(T13,AE13) -> 1 | AG13: =IF(AF13=B13,"совпадает","НЕ совпадает") -> совпадает
A14: 6 | B14: 0 | C14: =M13 -> 1 | D14: =C13 -> 0 | E14: =D13 -> 1 | F14: =E13 -> 0 | G14: =F13 -> 1 | H14: =G13 -> 0 | I14: =H13 -> 1 | J14: =I13 -> 0 | K14: =J13 -> 1 | L14: =K13 -> 0 | M14: =_xlfn.BITXOR(D14,_xlfn.BITXOR(H14,L14)) -> 0 | N14: =_xlfn.BITXOR(B14,M14) -> 0 | S14: 6 | T14: =N14 -> 0 | U14: =AE13 -> 1 | V14: =U13 -> 0 | W14: =V13 -> 1 | X14: =W13 -> 0 | Y14: =X13 -> 1 | Z14: =Y13 -> 0 | AA14: =Z13 -> 1 | AB14: =AA13 -> 0 | AC14: =AB13 -> 1 | AD14: =AC13 -> 0 | AE14: =_xlfn.BITXOR(V14,_xlfn.BITXOR(Z14,AD14)) -> 0 | AF14: =_xlfn.BITXOR(T14,AE14) -> 0 | AG14: =IF(AF14=B14,"совпадает","НЕ совпадает") -> совпадает
A15: 7 | B15: 0 | C15: =M14 -> 0 | D15: =C14 -> 1 | E15: =D14 -> 0 | F15: =E14 -> 1 | G15: =F14 -> 0 | H15: =G14 -> 1 | I15: =H14 -> 0 | J15: =I14 -> 1 | K15: =J14 -> 0 | L15: =K14 -> 1 | M15: =_xlfn.BITXOR(D15,_xlfn.BITXOR(H15,L15)) -> 1 | N15: =_xlfn.BITXOR(B15,M15) -> 1 | S15: 7 | T15: =N15 -> 1 | U15: =AE14 -> 0 | V15: =U14 -> 1 | W15: =V14 -> 0 | X15: =W14 -> 1 | Y15: =X14 -> 0 | Z15: =Y14 -> 1 | AA15: =Z14 -> 0 | AB15: =AA14 -> 1 | AC15: =AB14 -> 0 | AD15: =AC14 -> 1 | AE15: =_xlfn.BITXOR(V15,_xlfn.BITXOR(Z15,AD15)) -> 1 | AF15: =_xlfn.BITXOR(T15,AE15) -> 0 | AG15: =IF(AF15=B15,"совпадает","НЕ совпадает") -> совпадает
A16: 8 | B16: 1 | C16: =M15 -> 1 | D16: =C15 -> 0 | E16: =D15 -> 1 | F16: =E15 -> 0 | G16: =F15 -> 1 | H16: =G15 -> 0 | I16: =H15 -> 1 | J16: =I15 -> 0 | K16: =J15 -> 1 | L16: =K15 -> 0 | M16: =_xlfn.BITXOR(D16,_xlfn.BITXOR(H16,L16)) -> 0 | N16: =_xlfn.BITXOR(B16,M16) -> 1 | S16: 8 | T16: =N16 -> 1 | U16: =AE15 -> 1 | V16: =U15 -> 0 | W16: =V15 -> 1 | X16: =W15 -> 0 | Y16: =X15 -> 1 | Z16: =Y15 -> 0 | AA16: =Z15 -> 1 | AB16: =AA15 -> 0 | AC16: =AB15 -> 1 | AD16: =AC15 -> 0 | AE16: =_xlfn.BITXOR(V16,_xlfn.BITXOR(Z16,AD16)) -> 0 | AF16: =_xlfn.BITXOR(T16,AE16) -> 1 | AG16: =IF(AF16=B16,"совпадает","НЕ совпадает") -> совпадает
A17: 9 | B17: 0 | C17: =M16 -> 0 | D17: =C16 -> 1 | E17: =D16 -> 0 | F17: =E16 -> 1 | G17: =F16 -> 0 | H17: =G16 -> 1 | I17: =H16 -> 0 | J17: =I16 -> 1 | K17: =J16 -> 0 | L17: =K16 -> 1 | M17: =_xlfn.BITXOR(D17,_xlfn.BITXOR(H17,L17)) -> 1 | N17: =_xlfn.BITXOR(B17,M17) -> 1 | S17: 9 | T17: =N17 -> 1 | U17: =AE16 -> 0 | V17: =U16 -> 1 | W17: =V16 -> 0 | X17: =W16 -> 1 | Y17: =X16 -> 0 | Z17: =Y16 -> 1 | AA17: =Z16 -> 0 | AB17: =AA16 -> 1 | AC17: =AB16 -> 0 | AD17: =AC16 -> 1 | AE17: =_xlfn.BITXOR(V17,_xlfn.BITXOR(Z17,AD17)) -> 1 | AF17: =_xlfn.BITXOR(T17,AE17) -> 0 | AG17: =IF(AF17=B17,"совпадает","НЕ совпадает") -> совпадает
A18: 10 | B18: 0 | C18: =M17 -> 1 | D18: =C17 -> 0 | E18: =D17 -> 1 | F18: =E17 -> 0 | G18: =F17 -> 1 | H18: =G17 -> 0 | I18: =H17 -> 1 | J18: =I17 -> 0 | K18: =J17 -> 1 | L18: =K17 -> 0 | M18: =_xlfn.BITXOR(D18,_xlfn.BITXOR(H18,L18)) -> 0 | N18: =_xlfn.BITXOR(B18,M18) -> 0 | S18: 10 | T18: =N18 -> 0 | U18: =AE17 -> 1 | V18: =U17 -> 0 | W18: =V17 -> 1 | X18: =W17 -> 0 | Y18: =X17 -> 1 | Z18: =Y17 -> 0 | AA18: =Z17 -> 1 | AB18: =AA17 -> 0 | AC18: =AB17 -> 1 | AD18: =AC17 -> 0 | AE18: =_xlfn.BITXOR(V18,_xlfn.BITXOR(Z18,AD18)) -> 0 | AF18: =_xlfn.BITXOR(T18,AE18) -> 0 | AG18: =IF(AF18=B18,"совпадает","НЕ совпадает") -> совпадает
A20: Последовательность на выходе скремблера b_k | S20: Восстановленное сообщение
A21: =N9&N10&N11&N12&N13&N14&N15&N16&N17&N18 -> 1010001110 | S21: =AF9&AF10&AF11&AF12&AF13&AF14&AF15&AF16&AF17&AF18 -> 0000100100
S22: =IF(COUNTIF(AG9:AG18,"совпадает")=10,"сообщение восстановлено полностью","ошибка восстановления") -> сообщение восстановлено полностью
A24: Самосинхронизирующийся скремблер
A25: Начальное состояние регистра: нули (установка не требуется) | S25: Дескремблирование СС
A26: k | B26: a_k | C26: s1 | D26: s2 | E26: s3 | F26: s4 | G26: s5 | H26: s6 | I26: s7 | J26: s8 | K26: s9 | L26: s10 | M26: xor | N26: b_k | S26: k | T26: b_k | U26: s1 | V26: s2 | W26: s3 | X26: s4 | Y26: s5 | Z26: s6 | AA26: s7 | AB26: s8 | AC26: s9 | AD26: s10 | AE26: xor | AF26: a'_k | AG26: контроль
A27: 1 | B27: 0 | C27: 0 | D27: 0 | E27: 0 | F27: 0 | G27: 0 | H27: 0 | I27: 0 | J27: 0 | K27: 0 | L27: 0 | M27: =_xlfn.BITXOR(D27,_xlfn.BITXOR(H27,L27)) -> 0 | N27: =_xlfn.BITXOR(B27,M27) -> 0 | S27: 1 | T27: =N27 -> 0 | U27: 0 | V27: 0 | W27: 0 | X27: 0 | Y27: 0 | Z27: 0 | AA27: 0 | AB27: 0 | AC27: 0 | AD27: 0 | AE27: =_xlfn.BITXOR(V27,_xlfn.BITXOR(Z27,AD27)) -> 0 | AF27: =_xlfn.BITXOR(T27,AE27) -> 0 | AG27: =IF(AF27=B27,"совпадает","НЕ совпадает") -> совпадает
A28: 2 | B28: 0 | C28: =N27 -> 0 | D28: =C27 -> 0 | E28: =D27 -> 0 | F28: =E27 -> 0 | G28: =F27 -> 0 | H28: =G27 -> 0 | I28: =H27 -> 0 | J28: =I27 -> 0 | K28: =J27 -> 0 | L28: =K27 -> 0 | M28: =_xlfn.BITXOR(D28,_xlfn.BITXOR(H28,L28)) -> 0 | N28: =_xlfn.BITXOR(B28,M28) -> 0 | S28: 2 | T28: =N28 -> 0 | U28: =T27 -> 0 | V28: =U27 -> 0 | W28: =V27 -> 0 | X28: =W27 -> 0 | Y28: =X27 -> 0 | Z28: =Y27 -> 0 | AA28: =Z27 -> 0 | AB28: =AA27 -> 0 | ... AD28: =AC27 -> 0 | AE28: =_xlfn.BITXOR(V28,_xlfn.BITXOR(Z28,AD28)) -> 0 | AF28: =_xlfn.BITXOR(T28,AE28) -> 0 | AG28: =IF(AF28=B28,"совпадает","НЕ совпадает") -> совпадает
A29: 3 | B29: 0 | C29: =N28 -> 0 | D29: =C28 -> 0 | E29: =D28 -> 0 | F29: =E28 -> 0 | G29: =F28 -> 0 | H29: =G28 -> 0 | I29: =H28 -> 0 | J29: =I28 -> 0 | K29: =J28 -> 0 | L29: =K28 -> 0 | M29: =_xlfn.BITXOR(D29,_xlfn.BITXOR(H29,L29)) -> 0 | N29: =_xlfn.BITXOR(B29,M29) -> 0 | S29: 3 | T29: =N29 -> 0 | U29: =T28 -> 0 | V29: =U28 -> 0 | W29: =V28 -> 0 | X29: =W28 -> 0 | Y29: =X28 -> 0 | Z29: =Y28 -> 0 | AA29: =Z28 -> 0 | AB29: =AA28 -> 0 | ... AD29: =AC28 -> 0 | AE29: =_xlfn.BITXOR(V29,_xlfn.BITXOR(Z29,AD29)) -> 0 | AF29: =_xlfn.BITXOR(T29,AE29) -> 0 | AG29: =IF(AF29=B29,"совпадает","НЕ совпадает") -> совпадает
A30: 4 | B30: 0 | C30: =N29 -> 0 | D30: =C29 -> 0 | E30: =D29 -> 0 | F30: =E29 -> 0 | G30: =F29 -> 0 | H30: =G29 -> 0 | I30: =H29 -> 0 | J30: =I29 -> 0 | K30: =J29 -> 0 | L30: =K29 -> 0 | M30: =_xlfn.BITXOR(D30,_xlfn.BITXOR(H30,L30)) -> 0 | N30: =_xlfn.BITXOR(B30,M30) -> 0 | S30: 4 | T30: =N30 -> 0 | U30: =T29 -> 0 | V30: =U29 -> 0 | W30: =V29 -> 0 | X30: =W29 -> 0 | Y30: =X29 -> 0 | Z30: =Y29 -> 0 | AA30: =Z29 -> 0 | AB30: =AA29 -> 0 | ... AD30: =AC29 -> 0 | AE30: =_xlfn.BITXOR(V30,_xlfn.BITXOR(Z30,AD30)) -> 0 | AF30: =_xlfn.BITXOR(T30,AE30) -> 0 | AG30: =IF(AF30=B30,"совпадает","НЕ совпадает") -> совпадает
A31: 5 | B31: 1 | C31: =N30 -> 0 | D31: =C30 -> 0 | E31: =D30 -> 0 | F31: =E30 -> 0 | G31: =F30 -> 0 | H31: =G30 -> 0 | I31: =H30 -> 0 | J31: =I30 -> 0 | K31: =J30 -> 0 | L31: =K30 -> 0 | M31: =_xlfn.BITXOR(D31,_xlfn.BITXOR(H31,L31)) -> 0 | N31: =_xlfn.BITXOR(B31,M31) -> 1 | S31: 5 | T31: =N31 -> 1 | U31: =T30 -> 0 | V31: =U30 -> 0 | W31: =V30 -> 0 | X31: =W30 -> 0 | Y31: =X30 -> 0 | Z31: =Y30 -> 0 | AA31: =Z30 -> 0 | AB31: =AA30 -> 0 | ... AD31: =AC30 -> 0 | AE31: =_xlfn.BITXOR(V31,_xlfn.BITXOR(Z31,AD31)) -> 0 | AF31: =_xlfn.BITXOR(T31,AE31) -> 1 | AG31: =IF(AF31=B31,"совпадает","НЕ совпадает") -> совпадает
A32: 6 | B32: 0 | C32: =N31 -> 1 | D32: =C31 -> 0 | E32: =D31 -> 0 | F32: =E31 -> 0 | G32: =F31 -> 0 | H32: =G31 -> 0 | I32: =H31 -> 0 | J32: =I31 -> 0 | K32: =J31 -> 0 | L32: =K31 -> 0 | M32: =_xlfn.BITXOR(D32,_xlfn.BITXOR(H32,L32)) -> 0 | N32: =_xlfn.BITXOR(B32,M32) -> 0 | S32: 6 | T32: =N32 -> 0 | U32: =T31 -> 1 | V32: =U31 -> 0 | W32: =V31 -> 0 | X32: =W31 -> 0 | Y32: =X31 -> 0 | Z32: =Y31 -> 0 | AA32: =Z31 -> 0 | AB32: =AA31 -> 0 | ... AD32: =AC31 -> 0 | AE32: =_xlfn.BITXOR(V32,_xlfn.BITXOR(Z32,AD32)) -> 0 | AF32: =_xlfn.BITXOR(T32,AE32) -> 0 | AG32: =IF(AF32=B32,"совпадает","НЕ совпадает") -> совпадает
A33: 7 | B33: 0 | C33: =N32 -> 0 | D33: =C32 -> 1 | E33: =D32 -> 0 | F33: =E32 -> 0 | G33: =F32 -> 0 | H33: =G32 -> 0 | I33: =H32 -> 0 | J33: =I32 -> 0 | K33: =J32 -> 0 | L33: =K32 -> 0 | M33: =_xlfn.BITXOR(D33,_xlfn.BITXOR(H33,L33)) -> 1 | N33: =_xlfn.BITXOR(B33,M33) -> 1 | S33: 7 | T33: =N33 -> 1 | U33: =T32 -> 0 | V33: =U32 -> 1 | W33: =V32 -> 0 | X33: =W32 -> 0 | Y33: =X32 -> 0 | Z33: =Y32 -> 0 | AA33: =Z32 -> 0 | AB33: =AA32 -> 0 | ... AD33: =AC32 -> 0 | AE33: =_xlfn.BITXOR(V33,_xlfn.BITXOR(Z33,AD33)) -> 1 | AF33: =_xlfn.BITXOR(T33,AE33) -> 0 | AG33: =IF(AF33=B33,"совпадает","НЕ совпадает") -> совпадает
A34: 8 | B34: 1 | C34: =N33 -> 1 | D34: =C33 -> 0 | E34: =D33 -> 1 | F34: =E33 -> 0 | G34: =F33 -> 0 | H34: =G33 -> 0 | I34: =H33 -> 0 | J34: =I33 -> 0 | K34: =J33 -> 0 | L34: =K33 -> 0 | M34: =_xlfn.BITXOR(D34,_xlfn.BITXOR(H34,L34)) -> 0 | N34: =_xlfn.BITXOR(B34,M34) -> 1 | S34: 8 | T34: =N34 -> 1 | U34: =T33 -> 1 | V34: =U33 -> 0 | W34: =V33 -> 1 | X34: =W33 -> 0 | Y34: =X33 -> 0 | Z34: =Y33 -> 0 | AA34: =Z33 -> 0 | AB34: =AA33 -> 0 | ... AD34: =AC33 -> 0 | AE34: =_xlfn.BITXOR(V34,_xlfn.BITXOR(Z34,AD34)) -> 0 | AF34: =_xlfn.BITXOR(T34,AE34) -> 1 | AG34: =IF(AF34=B34,"совпадает","НЕ совпадает") -> совпадает
A35: 9 | B35: 0 | C35: =N34 -> 1 | D35: =C34 -> 1 | E35: =D34 -> 0 | F35: =E34 -> 1 | G35: =F34 -> 0 | H35: =G34 -> 0 | I35: =H34 -> 0 | J35: =I34 -> 0 | K35: =J34 -> 0 | L35: =K34 -> 0 | M35: =_xlfn.BITXOR(D35,_xlfn.BITXOR(H35,L35)) -> 1 | N35: =_xlfn.BITXOR(B35,M35) -> 1 | S35: 9 | T35: =N35 -> 1 | U35: =T34 -> 1 | V35: =U34 -> 1 | W35: =V34 -> 0 | X35: =W34 -> 1 | Y35: =X34 -> 0 | Z35: =Y34 -> 0 | AA35: =Z34 -> 0 | AB35: =AA34 -> 0 | ... AD35: =AC34 -> 0 | AE35: =_xlfn.BITXOR(V35,_xlfn.BITXOR(Z35,AD35)) -> 1 | AF35: =_xlfn.BITXOR(T35,AE35) -> 0 | AG35: =IF(AF35=B35,"совпадает","НЕ совпадает") -> совпадает
A36: 10 | B36: 0 | C36: =N35 -> 1 | D36: =C35 -> 1 | E36: =D35 -> 1 | F36: =E35 -> 0 | G36: =F35 -> 1 | H36: =G35 -> 0 | I36: =H35 -> 0 | J36: =I35 -> 0 | K36: =J35 -> 0 | L36: =K35 -> 0 | M36: =_xlfn.BITXOR(D36,_xlfn.BITXOR(H36,L36)) -> 1 | N36: =_xlfn.BITXOR(B36,M36) -> 1 | S36: 10 | T36: =N36 -> 1 | U36: =T35 -> 1 | V36: =U35 -> 1 | W36: =V35 -> 1 | X36: =W35 -> 0 | Y36: =X35 -> 1 | Z36: =Y35 -> 0 | AA36: =Z35 -> 0 | AB36: =AA35 -> 0 | ... AD36: =AC35 -> 0 | AE36: =_xlfn.BITXOR(V36,_xlfn.BITXOR(Z36,AD36)) -> 1 | AF36: =_xlfn.BITXOR(T36,AE36) -> 0 | AG36: =IF(AF36=B36,"совпадает","НЕ совпадает") -> совпадает
A38: Последовательность на выходе b_k (СС) | S38: Восстановленное сообщение
A39: =N27&N28&N29&N30&N31&N32&N33&N34&N35&N36 -> 0000101111 | S39: =AF27&AF28&AF29&AF30&AF31&AF32&AF33&AF34&AF35&AF36 -> 0000100100
S40: =IF(COUNTIF(AG27:AG36,"совпадает")=10,"сообщение восстановлено полностью","ошибка восстановления") -> сообщение восстановлено полностью
A44: в случае с СС на втором такте первый бит регистра равен выходному первого такта,
A45: а в случае с АД первый бит регистра равен не выходному первого такта, а результату XOR обратной связи без XOR с битом сообщения

Sheet 6
A1: Коды Хемминга (13,9) | C1: В соответствии с вариантом сформировать таблицу, в которой для заданного сообщения будет сформирована служебная информация. После этого изменить один из разрядов сообщения и продемонстрировать, как с помощью кода Хемминга будет обнаружена и справлена ошибка.
A2: № | B2: Передаваемое сообщение
A3: 10 | B3: 000100100
C4: 1 | D4: 2 | E4: 3 | F4: 4 | G4: 5 | H4: 6 | I4: 7 | J4: 8 | K4: 9
B5: Четность | C5: 0
B6: Информационные биты | C6: =VALUE(MID($B$3,C$4,1)) -> 0 | D6: =VALUE(MID($B$3,D$4,1)) -> 0 | E6: =VALUE(MID($B$3,E$4,1)) -> 0 | F6: =VALUE(MID($B$3,F$4,1)) -> 1 | G6: =VALUE(MID($B$3,G$4,1)) -> 0 | H6: =VALUE(MID($B$3,H$4,1)) -> 0 | I6: =VALUE(MID($B$3,I$4,1)) -> 1 | J6: =VALUE(MID($B$3,J$4,1)) -> 0 | K6: =VALUE(MID($B$3,K$4,1)) -> 0
C7: d1 | D7: d2 | E7: d3 | F7: d4 | G7: d5 | H7: d6 | I7: d7 | J7: d8 | K7: d9
B9: № позиции | C9: № в дв. (8-4-2-1) | D9: входит в p1 | E9: входит в p2 | F9: входит в p4 | G9: входит в p8 | H9: тип | I9: значение бита
B10: 1 | C10: =G10&F10&E10&D10 -> 0001 | D10: =MOD(B10,2) -> 1 | E10: =MOD(INT(B10/2),2) -> 0 | F10: =MOD(INT(B10/4),2) -> 0 | G10: =MOD(INT(B10/8),2) -> 0 | H10: =IF(OR(B10=1,B10=2,B10=4,B10=8),"контрольный","информационный") -> контрольный | I10: =MOD(_xlfn.XOR($C$6,$D$6,$F$6,$G$6,$I$6,$K$6)+$C$5,2) -> 0
B11: 2 | C11: =G11&F11&E11&D11 -> 0010 | D11: =MOD(B11,2) -> 0 | E11: =MOD(INT(B11/2),2) -> 1 | F11: =MOD(INT(B11/4),2) -> 0 | G11: =MOD(INT(B11/8),2) -> 0 | H11: =IF(OR(B11=1,B11=2,B11=4,B11=8),"контрольный","информационный") -> контрольный | I11: =MOD(_xlfn.XOR($C$6,$E$6,$F$6,$H$6,$I$6)+$C$5,2) -> 0
B12: 3 | C12: =G12&F12&E12&D12 -> 0011 | D12: =MOD(B12,2) -> 1 | E12: =MOD(INT(B12/2),2) -> 1 | F12: =MOD(INT(B12/4),2) -> 0 | G12: =MOD(INT(B12/8),2) -> 0 | H12: =IF(OR(B12=1,B12=2,B12=4,B12=8),"контрольный","информационный") -> информационный | I12: =INDEX($C$6:$K$6,1) -> 0
B13: 4 | C13: =G13&F13&E13&D13 -> 0100 | D13: =MOD(B13,2) -> 0 | E13: =MOD(INT(B13/2),2) -> 0 | F13: =MOD(INT(B13/4),2) -> 1 | G13: =MOD(INT(B13/8),2) -> 0 | H13: =IF(OR(B13=1,B13=2,B13=4,B13=8),"контрольный","информационный") -> контрольный | I13: =MOD(_xlfn.XOR($D$6,$E$6,$F$6,$J$6,$K$6)+$C$5,2) -> 1
B14: 5 | C14: =G14&F14&E14&D14 -> 0101 | D14: =MOD(B14,2) -> 1 | E14: =MOD(INT(B14/2),2) -> 0 | F14: =MOD(INT(B14/4),2) -> 1 | G14: =MOD(INT(B14/8),2) -> 0 | H14: =IF(OR(B14=1,B14=2,B14=4,B14=8),"контрольный","информационный") -> информационный | I14: =INDEX($C$6:$K$6,2) -> 0
B15: 6 | C15: =G15&F15&E15&D15 -> 0110 | D15: =MOD(B15,2) -> 0 | E15: =MOD(INT(B15/2),2) -> 1 | F15: =MOD(INT(B15/4),2) -> 1 | G15: =MOD(INT(B15/8),2) -> 0 | H15: =IF(OR(B15=1,B15=2,B15=4,B15=8),"контрольный","информационный") -> информационный | I15: =INDEX($C$6:$K$6,3) -> 0
B16: 7 | C16: =G16&F16&E16&D16 -> 0111 | D16: =MOD(B16,2) -> 1 | E16: =MOD(INT(B16/2),2) -> 1 | F16: =MOD(INT(B16/4),2) -> 1 | G16: =MOD(INT(B16/8),2) -> 0 | H16: =IF(OR(B16=1,B16=2,B16=4,B16=8),"контрольный","информационный") -> информационный | I16: =INDEX($C$6:$K$6,4) -> 1
B17: 8 | C17: =G17&F17&E17&D17 -> 1000 | D17: =MOD(B17,2) -> 0 | E17: =MOD(INT(B17/2),2) -> 0 | F17: =MOD(INT(B17/4),2) -> 0 | G17: =MOD(INT(B17/8),2) -> 1 | H17: =IF(OR(B17=1,B17=2,B17=4,B17=8),"контрольный","информационный") -> контрольный | I17: =MOD(_xlfn.XOR($G$6,$H$6,$I$6,$J$6,$K$6)+$C$5,2) -> 1
B18: 9 | C18: =G18&F18&E18&D18 -> 1001 | D18: =MOD(B18,2) -> 1 | E18: =MOD(INT(B18/2),2) -> 0 | F18: =MOD(INT(B18/4),2) -> 0 | G18: =MOD(INT(B18/8),2) -> 1 | H18: =IF(OR(B18=1,B18=2,B18=4,B18=8),"контрольный","информационный") -> информационный | I18: =INDEX($C$6:$K$6,5) -> 0
B19: 10 | C19: =G19&F19&E19&D19 -> 1010 | D19: =MOD(B19,2) -> 0 | E19: =MOD(INT(B19/2),2) -> 1 | F19: =MOD(INT(B19/4),2) -> 0 | G19: =MOD(INT(B19/8),2) -> 1 | H19: =IF(OR(B19=1,B19=2,B19=4,B19=8),"контрольный","информационный") -> информационный | I19: =INDEX($C$6:$K$6,6) -> 0
B20: 11 | C20: =G20&F20&E20&D20 -> 1011 | D20: =MOD(B20,2) -> 1 | E20: =MOD(INT(B20/2),2) -> 1 | F20: =MOD(INT(B20/4),2) -> 0 | G20: =MOD(INT(B20/8),2) -> 1 | H20: =IF(OR(B20=1,B20=2,B20=4,B20=8),"контрольный","информационный") -> информационный | I20: =INDEX($C$6:$K$6,7) -> 1
B21: 12 | C21: =G21&F21&E21&D21 -> 1100 | D21: =MOD(B21,2) -> 0 | E21: =MOD(INT(B21/2),2) -> 0 | F21: =MOD(INT(B21/4),2) -> 1 | G21: =MOD(INT(B21/8),2) -> 1 | H21: =IF(OR(B21=1,B21=2,B21=4,B21=8),"контрольный","информационный") -> информационный | I21: =INDEX($C$6:$K$6,8) -> 0
B22: 13 | C22: =G22&F22&E22&D22 -> 1101 | D22: =MOD(B22,2) -> 1 | E22: =MOD(INT(B22/2),2) -> 0 | F22: =MOD(INT(B22/4),2) -> 1 | G22: =MOD(INT(B22/8),2) -> 1 | H22: =IF(OR(B22=1,B22=2,B22=4,B22=8),"контрольный","информационный") -> информационный | I22: =INDEX($C$6:$K$6,9) -> 0
B24: Кодовое слово | C24: =I10&I11&I12&I13&I14&I15&I16&I17&I18&I19&I20&I21&I22 -> 0001001100100
B25: Контрольные биты p1..p8 = позиции 1,2,4,8.
B27: Обнаружение и исправление однократной ошибки
B28: Позиция искажённого бита | C28: 7 | E28: Позиция исправления | H28: =D51 -> 7
B30: № позиции | C30: передано | D30: принято | E30: p1 | F30: p2 | G30: p4 | H30: p8 | I30: исправлено | J30: контроль
B31: 1 | C31: =I10 -> 0 | D31: =IF($C$28=B31,1-C31,C31) -> 0 | E31: =MOD(INT(B31/1),2) -> 1 | F31: =MOD(INT(B31/2),2) -> 0 | G31: =MOD(INT(B31/4),2) -> 0 | H31: =MOD(INT(B31/8),2) -> 0 | I31: =IF(B31=$H$28,1-D31,D31) -> 0 | J31: =IF(I31=C31,"совпадает","НЕ совпадает") -> совпадает
B32: 2 | C32: =I11 -> 0 | D32: =IF($C$28=B32,1-C32,C32) -> 0 | E32: =MOD(INT(B32/1),2) -> 0 | F32: =MOD(INT(B32/2),2) -> 1 | G32: =MOD(INT(B32/4),2) -> 0 | H32: =MOD(INT(B32/8),2) -> 0 | I32: =IF(B32=$H$28,1-D32,D32) -> 0 | J32: =IF(I32=C32,"совпадает","НЕ совпадает") -> совпадает
B33: 3 | C33: =I12 -> 0 | D33: =IF($C$28=B33,1-C33,C33) -> 0 | E33: =MOD(INT(B33/1),2) -> 1 | F33: =MOD(INT(B33/2),2) -> 1 | G33: =MOD(INT(B33/4),2) -> 0 | H33: =MOD(INT(B33/8),2) -> 0 | I33: =IF(B33=$H$28,1-D33,D33) -> 0 | J33: =IF(I33=C33,"совпадает","НЕ совпадает") -> совпадает
B34: 4 | C34: =I13 -> 1 | D34: =IF($C$28=B34,1-C34,C34) -> 1 | E34: =MOD(INT(B34/1),2) -> 0 | F34: =MOD(INT(B34/2),2) -> 0 | G34: =MOD(INT(B34/4),2) -> 1 | H34: =MOD(INT(B34/8),2) -> 0 | I34: =IF(B34=$H$28,1-D34,D34) -> 1 | J34: =IF(I34=C34,"совпадает","НЕ совпадает") -> совпадает
B35: 5 | C35: =I14 -> 0 | D35: =IF($C$28=B35,1-C35,C35) -> 0 | E35: =MOD(INT(B35/1),2) -> 1 | F35: =MOD(INT(B35/2),2) -> 0 | G35: =MOD(INT(B35/4),2) -> 1 | H35: =MOD(INT(B35/8),2) -> 0 | I35: =IF(B35=$H$28,1-D35,D35) -> 0 | J35: =IF(I35=C35,"совпадает","НЕ совпадает") -> совпадает
B36: 6 | C36: =I15 -> 0 | D36: =IF($C$28=B36,1-C36,C36) -> 0 | E36: =MOD(INT(B36/1),2) -> 0 | F36: =MOD(INT(B36/2),2) -> 1 | G36: =MOD(INT(B36/4),2) -> 1 | H36: =MOD(INT(B36/8),2) -> 0 | I36: =IF(B36=$H$28,1-D36,D36) -> 0 | J36: =IF(I36=C36,"совпадает","НЕ совпадает") -> совпадает
B37: 7 | C37: =I16 -> 1 | D37: =IF($C$28=B37,1-C37,C37) -> 0 | E37: =MOD(INT(B37/1),2) -> 1 | F37: =MOD(INT(B37/2),2) -> 1 | G37: =MOD(INT(B37/4),2) -> 1 | H37: =MOD(INT(B37/8),2) -> 0 | I37: =IF(B37=$H$28,1-D37,D37) -> 1 | J37: =IF(I37=C37,"совпадает","НЕ совпадает") -> совпадает
B38: 8 | C38: =I17 -> 1 | D38: =IF($C$28=B38,1-C38,C38) -> 1 | E38: =MOD(INT(B38/1),2) -> 0 | F38: =MOD(INT(B38/2),2) -> 0 | G38: =MOD(INT(B38/4),2) -> 0 | H38: =MOD(INT(B38/8),2) -> 1 | I38: =IF(B38=$H$28,1-D38,D38) -> 1 | J38: =IF(I38=C38,"совпадает","НЕ совпадает") -> совпадает
B39: 9 | C39: =I18 -> 0 | D39: =IF($C$28=B39,1-C39,C39) -> 0 | E39: =MOD(INT(B39/1),2) -> 1 | F39: =MOD(INT(B39/2),2) -> 0 | G39: =MOD(INT(B39/4),2) -> 0 | H39: =MOD(INT(B39/8),2) -> 1 | I39: =IF(B39=$H$28,1-D39,D39) -> 0 | J39: =IF(I39=C39,"совпадает","НЕ совпадает") -> совпадает
B40: 10 | C40: =I19 -> 0 | D40: =IF($C$28=B40,1-C40,C40) -> 0 | E40: =MOD(INT(B40/1),2) -> 0 | F40: =MOD(INT(B40/2),2) -> 1 | G40: =MOD(INT(B40/4),2) -> 0 | H40: =MOD(INT(B40/8),2) -> 1 | I40: =IF(B40=$H$28,1-D40,D40) -> 0 | J40: =IF(I40=C40,"совпадает","НЕ совпадает") -> совпадает
B41: 11 | C41: =I20 -> 1 | D41: =IF($C$28=B41,1-C41,C41) -> 1 | E41: =MOD(INT(B41/1),2) -> 1 | F41: =MOD(INT(B41/2),2) -> 1 | G41: =MOD(INT(B41/4),2) -> 0 | H41: =MOD(INT(B41/8),2) -> 1 | I41: =IF(B41=$H$28,1-D41,D41) -> 1 | J41: =IF(I41=C41,"совпадает","НЕ совпадает") -> совпадает
B42: 12 | C42: =I21 -> 0 | D42: =IF($C$28=B42,1-C42,C42) -> 0 | E42: =MOD(INT(B42/1),2) -> 0 | F42: =MOD(INT(B42/2),2) -> 0 | G42: =MOD(INT(B42/4),2) -> 1 | H42: =MOD(INT(B42/8),2) -> 1 | I42: =IF(B42=$H$28,1-D42,D42) -> 0 | J42: =IF(I42=C42,"совпадает","НЕ совпадает") -> совпадает
B43: 13 | C43: =I22 -> 0 | D43: =IF($C$28=B43,1-C43,C43) -> 0 | E43: =MOD(INT(B43/1),2) -> 1 | F43: =MOD(INT(B43/2),2) -> 0 | G43: =MOD(INT(B43/4),2) -> 1 | H43: =MOD(INT(B43/8),2) -> 1 | I43: =IF(B43=$H$28,1-D43,D43) -> 0 | J43: =IF(I43=C43,"совпадает","НЕ совпадает") -> совпадает
B45: Синдром, проверка чётности групп по принятым битам
...

Sheet 7
A1: ПР7. Вариант 10, образующий полином g(X)=X^3+X^2+1 | AF1: Таблица вторичных кодов степеней двойки
A2: Биты полинома g3 g2 g1 g0 | J2: 1 | K2: 1 | L2: 0 | M2: 1 | O2: g = | P2: =J2&K2&L2&M2 -> 1101 | AF2: Первичный код (ПК) | AG2: ПК bin | AO2: ВК дел | AP2: ВК умн
A3: Число 1: деление полиномов (делимое = инфо*X^3) | R3: Число 1: умножение полиномов инфо*g | AF3: 1 | AG3: =DEC2BIN(AF3,4) -> 0001 | AH3: =MID(AG3,1,1) -> 0 | AI3: =MID(AG3,2,1) -> 0 | AJ3: =MID(AG3,3,1) -> 0 | AK3: =MID(AG3,4,1) -> 1 | AL3: =MID(G14,5,1) -> 1 | AM3: =MID(G14,6,1) -> 0 | AN3: =MID(G14,7,1) -> 1 | AO3: =AH3&AI3&AJ3&AK3&AL3&AM3&AN3 -> 0001101 | AP3: =X6 -> 0001101
A4: =DEC2BIN(1,4)&"000" -> 0001000 | D4: делимое: | S4: =MID(DEC2BIN(1,4),1,1) -> 0 | T4: =MID(DEC2BIN(1,4),2,1) -> 0 | U4: =MID(DEC2BIN(1,4),3,1) -> 0 | V4: =MID(DEC2BIN(1,4),4,1) -> 1 | AF4: 2 | AG4: =DEC2BIN(AF4,4) -> 0010 | AH4: =MID(AG4,1,1) -> 0 | AI4: =MID(AG4,2,1) -> 0 | AJ4: =MID(AG4,3,1) -> 1 | AK4: =MID(AG4,4,1) -> 0 | AL4: =MID(G27,5,1) -> 1 | AM4: =MID(G27,6,1) -> 1 | AN4: =MID(G27,7,1) -> 1 | AO4: =AH4&AI4&AJ4&AK4&AL4&AM4&AN4 -> 0010111 | AP4: =X19 -> 0011010
A5: t | B5: b | C5: f | D5: r2 | E5: r1 | F5: r0 | S5: =MOD(S4*$J$2,2) -> 0 | T5: =MOD(S4*$K$2+T4*$J$2,2) -> 0 | U5: =MOD(S4*$L$2+T4*$K$2+U4*$J$2,2) -> 0 | V5: =MOD(S4*$M$2+T4*$L$2+U4*$K$2+V4*$J$2,2) -> 1 | W5: =MOD(T4*$M$2+U4*$L$2+V4*$K$2,2) -> 1 | X5: =MOD(U4*$M$2+V4*$L$2,2) -> 0 | Y5: =MOD(V4*$M$2,2) -> 1 | AF5: 4 | AG5: =DEC2BIN(AF5,4) -> 0100 | AH5: =MID(AG5,1,1) -> 0 | AI5: =MID(AG5,2,1) -> 1 | AJ5: =MID(AG5,3,1) -> 0 | AK5: =MID(AG5,4,1) -> 0 | AL5: =MID(G40,5,1) -> 0 | AM5: =MID(G40,6,1) -> 1 | AN5: =MID(G40,7,1) -> 1 | AO5: =AH5&AI5&AJ5&AK5&AL5&AM5&AN5 -> 0100011 | AP5: =X32 -> 0110100
A6: 1 | B6: =MID($A$4,A6,1) -> 0 | C6: =0 -> 0 | D6: =0 -> 0 | E6: =0 -> 0 | F6: =MOD(B6,2) -> 0 | R6: Вторичный код | X6: =S5&T5&U5&V5&W5&X5&Y5 -> 0001101 | AF6: 8 | AG6: =DEC2BIN(AF6,4) -> 1000 | AH6: =MID(AG6,1,1) -> 1 | AI6: =MID(AG6,2,1) -> 0 | AJ6: =MID(AG6,3,1) -> 0 | AK6: =MID(AG6,4,1) -> 0 | AL6: =MID(G53,5,1) -> 1 | AM6: =MID(G53,6,1) -> 1 | AN6: =MID(G53,7,1) -> 0 | AO6: =AH6&AI6&AJ6&AK6&AL6&AM6&AN6 -> 1000110 | AP6: =X45 -> 1101000
A7: 2 | B7: =MID($A$4,A7,1) -> 0 | C7: =D6 -> 0 | D7: =MOD(E6+D6*$K$2,2) -> 0 | E7: =MOD(F6+D6*$L$2,2) -> 0 | F7: =MOD(B7+D6*$M$2,2) -> 0
A8: 3 | B8: =MID($A$4,A8,1) -> 0 | C8: =D7 -> 0 | D8: =MOD(E7+D7*$K$2,2) -> 0 | E8: =MOD(F7+D7*$L$2,2) -> 0 | F8: =MOD(B8+D7*$M$2,2) -> 0
A9: 4 | B9: =MID($A$4,A9,1) -> 1 | C9: =D8 -> 0 | D9: =MOD(E8+D8*$K$2,2) -> 0 | E9: =MOD(F8+D8*$L$2,2) -> 0 | F9: =MOD(B9+D8*$M$2,2) -> 1
A10: 5 | B10: =MID($A$4,A10,1) -> 0 | C10: =D9 -> 0 | D10: =MOD(E9+D9*$K$2,2) -> 0 | E10: =MOD(F9+D9*$L$2,2) -> 1 | F10: =MOD(B10+D9*$M$2,2) -> 0
A11: 6 | B11: =MID($A$4,A11,1) -> 0 | C11: =D10 -> 0 | D11: =MOD(E10+D10*$K$2,2) -> 1 | E11: =MOD(F10+D10*$L$2,2) -> 0 | F11: =MOD(B11+D10*$M$2,2) -> 0
A12: 7 | B12: =MID($A$4,A12,1) -> 0 | C12: =D11 -> 1 | D12: =MOD(E11+D11*$K$2,2) -> 1 | E12: =MOD(F11+D11*$L$2,2) -> 0 | F12: =MOD(B12+D11*$M$2,2) -> 1
A13: Остаток R(X): | F13: =D12&E12&F12 -> 101
A14: Вторичный код | G14: =DEC2BIN(1,4)&F13 -> 0001101
A16: Число 2: деление полиномов (делимое = инфо*X^3) | R16: Число 2: умножение полиномов инфо*g
A17: =DEC2BIN(2,4)&"000" -> 0010000 | D17: делимое: | S17: =MID(DEC2BIN(2,4),1,1) -> 0 | T17: =MID(DEC2BIN(2,4),2,1) -> 0 | U17: =MID(DEC2BIN(2,4),3,1) -> 1 | V17: =MID(DEC2BIN(2,4),4,1) -> 0
A18: t | B18: b | C18: f | D18: r2 | E18: r1 | F18: r0 | S18: =MOD(S17*$J$2,2) -> 0 | T18: =MOD(S17*$K$2+T17*$J$2,2) -> 0 | U18: =MOD(S17*$L$2+T17*$K$2+U17*$J$2,2) -> 1 | V18: =MOD(S17*$M$2+T17*$L$2+U17*$K$2+V17*$J$2,2) -> 1 | W18: =MOD(T17*$M$2+U17*$L$2+V17*$K$2,2) -> 0 | X18: =MOD(U17*$M$2+V17*$L$2,2) -> 1 | Y18: =MOD(V17*$M$2,2) -> 0
A19: 1 | B19: =MID($A$17,A19,1) -> 0 | C19: =0 -> 0 | D19: =0 -> 0 | E19: =0 -> 0 | F19: =MOD(B19,2) -> 0 | R19: Вторичный код | X19: =S18&T18&U18&V18&W18&X18&Y18 -> 0011010
A20: 2 | B20: =MID($A$17,A20,1) -> 0 | C20: =D19 -> 0 | D20: =MOD(E19+D19*$K$2,2) -> 0 | E20: =MOD(F19+D19*$L$2,2) -> 0 | F20: =MOD(B20+D19*$M$2,2) -> 0
A21: 3 | B21: =MID($A$17,A21,1) -> 1 | C21: =D20 -> 0 | D21: =MOD(E20+D20*$K$2,2) -> 0 | E21: =MOD(F20+D20*$L$2,2) -> 0 | F21: =MOD(B21+D20*$M$2,2) -> 1
A22: 4 | B22: =MID($A$17,A22,1) -> 0 | C22: =D21 -> 0 | D22: =MOD(E21+D21*$K$2,2) -> 0 | E22: =MOD(F21+D21*$L$2,2) -> 1 | F22: =MOD(B22+D21*$M$2,2) -> 0
A23: 5 | B23: =MID($A$17,A23,1) -> 0 | C23: =D22 -> 0 | D23: =MOD(E22+D22*$K$2,2) -> 1 | E23: =MOD(F22+D22*$L$2,2) -> 0 | F23: =MOD(B23+D22*$M$2,2) -> 0
A24: 6 | B24: =MID($A$17,A24,1) -> 0 | C24: =D23 -> 1 | D24: =MOD(E23+D23*$K$2,2) -> 1 | E24: =MOD(F23+D23*$L$2,2) -> 0 | F24: =MOD(B24+D23*$M$2,2) -> 1
A25: 7 | B25: =MID($A$17,A25,1) -> 0 | C25: =D24 -> 1 | D25: =MOD(E24+D24*$K$2,2) -> 1 | E25: =MOD(F24+D24*$L$2,2) -> 1 | F25: =MOD(B25+D24*$M$2,2) -> 1
A26: Остаток R(X): | F26: =D25&E25&F25 -> 111
A27: Вторичный код | G27: =DEC2BIN(2,4)&F26 -> 0010111
A29: Число 4: деление полиномов (делимое = инфо*X^3) | R29: Число 4: умножение полиномов инфо*g
A30: =DEC2BIN(4,4)&"000" -> 0100000 | D30: делимое: | S30: =MID(DEC2BIN(4,4),1,1) -> 0 | T30: =MID(DEC2BIN(4,4),2,1) -> 1 | U30: =MID(DEC2BIN(4,4),3,1) -> 0 | V30: =MID(DEC2BIN(4,4),4,1) -> 0
A31: t | B31: b | C31: f | D31: r2 | E31: r1 | F31: r0 | S31: =MOD(S30*$J$2,2) -> 0 | T31: =MOD(S30*$K$2+T30*$J$2,2) -> 1 | U31: =MOD(S30*$L$2+T30*$K$2+U30*$J$2,2) -> 1 | V31: =MOD(S30*$M$2+T30*$L$2+U30*$K$2+V30*$J$2,2) -> 0 | W31: =MOD(T30*$M$2+U30*$L$2+V30*$K$2,2) -> 1 | X31: =MOD(U30*$M$2+V30*$L$2,2) -> 0 | Y31: =MOD(V30*$M$2,2) -> 0
A32: 1 | B32: =MID($A$30,A32,1) -> 0 | C32: =0 -> 0 | D32: =0 -> 0 | E32: =0 -> 0 | F32: =MOD(B32,2) -> 0 | R32: Вторичный код | X32: =S31&T31&U31&V31&W31&X31&Y31 -> 0110100
A33: 2 | B33: =MID($A$30,A33,1) -> 1 | C33: =D32 -> 0 | D33: =MOD(E32+D32*$K$2,2) -> 0 | E33: =MOD(F32+D32*$L$2,2) -> 0 | F33: =MOD(B33+D32*$M$2,2) -> 1
A34: 3 | B34: =MID($A$30,A34,1) -> 0 | C34: =D33 -> 0 | D34: =MOD(E33+D33*$K$2,2) -> 0 | E34: =MOD(F33+D33*$L$2,2) -> 1 | F34: =MOD(B34+D33*$M$2,2) -> 0
A35: 4 | B35: =MID($A$30,A35,1) -> 0 | C35: =D34 -> 0 | D35: =MOD(E34+D34*$K$2,2) -> 1 | E35: =MOD(F34+D34*$L$2,2) -> 0 | F35: =MOD(B35+D34*$M$2,2) -> 0
A36: 5 | B36: =MID($A$30,A36,1) -> 0 | C36: =D35 -> 1 | D36: =MOD(E35+D35*$K$2,2) -> 1 | E36: =MOD(F35+D35*$L$2,2) -> 0 | F36: =MOD(B36+D35*$M$2,2) -> 1
A37: 6 | B37: =MID($A$30,A37,1) -> 0 | C37: =D36 -> 1 | D37: =MOD(E36+D36*$K$2,2) -> 1 | E37: =MOD(F36+D36*$L$2,2) -> 1 | F37: =MOD(B37+D36*$M$2,2) -> 1
A38: 7 | B38: =MID($A$30,A38,1) -> 0 | C38: =D37 -> 1 | D38: =MOD(E37+D37*$K$2,2) -> 0 | E38: =MOD(F37+D37*$L$2,2) -> 1 | F38: =MOD(B38+D37*$M$2,2) -> 1
A39: Остаток R(X): | F39: =D38&E38&F38 -> 011
A40: Вторичный код | G40: =DEC2BIN(4,4)&F39 -> 0100011
A42: Число 8: деление полиномов (делимое = инфо*X^3) | R42: Число 8: умножение полиномов инфо*g
A43: =DEC2BIN(8,4)&"000" -> 1000000 | D43: делимое: | S43: =MID(DEC2BIN(8,4),1,1) -> 1 | T43: =MID(DEC2BIN(8,4),2,1) -> 0 | U43: =MID(DEC2BIN(8,4),3,1) -> 0 | V43: =MID(DEC2BIN(8,4),4,1) -> 0
...

Sheet 8
A1: ПР8. Вариант 10, g=1101. Анализ циклического кода (7,4)
E2: входит в диапазон
A3: № | B3: ВК bin | C3: ВК hex | D3: сдвиг | F3: вес | G3: кроме 0
A4: 0 | B4: ='7'!W57 -> 0000000 | C4: =DEC2HEX(BIN2DEC(B4),2) -> 00 | D4: =MID(B4,7,1)&LEFT(B4,6) -> 0000000 | E4: =IF(COUNTIF($B$4:$B$19,D4)>0,"да","нет") -> да | F4: =SUM('7'!O57:U57) -> 0 | G4: =IF(F4=0,"",F4)
A5: 1 | B5: ='7'!W58 -> 0001101 | C5: =DEC2HEX(BIN2DEC(B5),2) -> 0D | D5: =MID(B5,7,1)&LEFT(B5,6) -> 1000110 | E5: =IF(COUNTIF($B$4:$B$19,D5)>0,"да","нет") -> да | F5: =SUM('7'!O58:U58) -> 3 | G5: =IF(F5=0,"",F5) -> 3
A6: 2 | B6: ='7'!W59 -> 0010111 | C6: =DEC2HEX(BIN2DEC(B6),2) -> 17 | D6: =MID(B6,7,1)&LEFT(B6,6) -> 1001011 | E6: =IF(COUNTIF($B$4:$B$19,D6)>0,"да","нет") -> да | F6: =SUM('7'!O59:U59) -> 4 | G6: =IF(F6=0,"",F6) -> 4
A7: 3 | B7: ='7'!W60 -> 0011010 | C7: =DEC2HEX(BIN2DEC(B7),2) -> 1A | D7: =MID(B7,7,1)&LEFT(B7,6) -> 0001101 | E7: =IF(COUNTIF($B$4:$B$19,D7)>0,"да","нет") -> да | F7: =SUM('7'!O60:U60) -> 3 | G7: =IF(F7=0,"",F7) -> 3
A8: 4 | B8: ='7'!W61 -> 0100011 | C8: =DEC2HEX(BIN2DEC(B8),2) -> 23 | D8: =MID(B8,7,1)&LEFT(B8,6) -> 1010001 | E8: =IF(COUNTIF($B$4:$B$19,D8)>0,"да","нет") -> да | F8: =SUM('7'!O61:U61) -> 3 | G8: =IF(F8=0,"",F8) -> 3
A9: 5 | B9: ='7'!W62 -> 0101110 | C9: =DEC2HEX(BIN2DEC(B9),2) -> 2E | D9: =MID(B9,7,1)&LEFT(B9,6) -> 0010111 | E9: =IF(COUNTIF($B$4:$B$19,D9)>0,"да","нет") -> да | F9: =SUM('7'!O62:U62) -> 4 | G9: =IF(F9=0,"",F9) -> 4
A10: 6 | B10: ='7'!W63 -> 0110100 | C10: =DEC2HEX(BIN2DEC(B10),2) -> 34 | D10: =MID(B10,7,1)&LEFT(B10,6) -> 0011010 | E10: =IF(COUNTIF($B$4:$B$19,D10)>0,"да","нет") -> да | F10: =SUM('7'!O63:U63) -> 3 | G10: =IF(F10=0,"",F10) -> 3
A11: 7 | B11: ='7'!W64 -> 0111001 | C11: =DEC2HEX(BIN2DEC(B11),2) -> 39 | D11: =MID(B11,7,1)&LEFT(B11,6) -> 1011100 | E11: =IF(COUNTIF($B$4:$B$19,D11)>0,"да","нет") -> да | F11: =SUM('7'!O64:U64) -> 4 | G11: =IF(F11=0,"",F11) -> 4
A12: 8 | B12: ='7'!W65 -> 1000110 | C12: =DEC2HEX(BIN2DEC(B12),2) -> 46 | D12: =MID(B12,7,1)&LEFT(B12,6) -> 0100011 | E12: =IF(COUNTIF($B$4:$B$19,D12)>0,"да","нет") -> да | F12: =SUM('7'!O65:U65) -> 3 | G12: =IF(F12=0,"",F12) -> 3
A13: 9 | B13: ='7'!W66 -> 1001011 | C13: =DEC2HEX(BIN2DEC(B13),2) -> 4B | D13: =MID(B13,7,1)&LEFT(B13,6) -> 1100101 | E13: =IF(COUNTIF($B$4:$B$19,D13)>0,"да","нет") -> да | F13: =SUM('7'!O66:U66) -> 4 | G13: =IF(F13=0,"",F13) -> 4
A14: 10 | B14: ='7'!W67 -> 1010001 | C14: =DEC2HEX(BIN2DEC(B14),2) -> 51 | D14: =MID(B14,7,1)&LEFT(B14,6) -> 1101000 | E14: =IF(COUNTIF($B$4:$B$19,D14)>0,"да","нет") -> да | F14: =SUM('7'!O67:U67) -> 3 | G14: =IF(F14=0,"",F14) -> 3
A15: 11 | B15: ='7'!W68 -> 1011100 | C15: =DEC2HEX(BIN2DEC(B15),2) -> 5C | D15: =MID(B15,7,1)&LEFT(B15,6) -> 0101110 | E15: =IF(COUNTIF($B$4:$B$19,D15)>0,"да","нет") -> да | F15: =SUM('7'!O68:U68) -> 4 | G15: =IF(F15=0,"",F15) -> 4
... A19: 15 | B19: ='7'!W72 -> 1111111 | C19: =DEC2HEX(BIN2DEC(B19),2) -> 7F | D19: =MID(B19,7,1)&LEFT(B19,6) -> 1111111 | E19: =IF(COUNTIF($B$4:$B$19,D19)>0,"да","нет") -> да | F19: =SUM('7'!O72:U72) -> 7 | G19: =IF(F19=0,"",F19) -> 7
A20: Распределение по весам
B21: вес | C21: число кодов
B22: 0 | C22: =COUNTIF($F$4:$F$19,B22) -> 1
B23: 1 | C23: =COUNTIF($F$4:$F$19,B23) -> 0
B24: 2 | C24: =COUNTIF($F$4:$F$19,B24) -> 0
B25: 3 | C25: =COUNTIF($F$4:$F$19,B25) -> 7
B26: 4 | C26: =COUNTIF($F$4:$F$19,B26) -> 7
B27: 5 | C27: =COUNTIF($F$4:$F$19,B27) -> 0
B28: 6 | C28: =COUNTIF($F$4:$F$19,B28) -> 0
B29: 7 | C29: =COUNTIF($F$4:$F$19,B29) -> 1
A31: Минимальное расстояние Хемминга | F31: =MIN(G4:G19) -> 3 | G31: для линейного кода d_min = минимальный ненулевой вес
A34: Матрица межкодовых расстояний
B35: 0 | C35: 1 | D35: 2 | E35: 3 | F35: 4 | G35: 5 | H35: 6 | I35: 7 | J35: 8 | K35: 9 | L35: 10 | M35: 11 | N35: 12 | O35: 13 | P35: 14 | Q35: 15
A36: 0 | B36: {=SUMPRODUCT(ABS('7'!$O57:$U57-'7'!$O$57:$U$57))} -> 0 | C36: {=SUMPRODUCT(ABS('7'!$O57:$U57-'7'!$O$58:$U$58))} -> 3 | D36: {=SUMPRODUCT(ABS('7'!$O57:$U57-'7'!$O$59:$U$59))} -> 4 | E36: {=SUMPRODUCT(ABS('7'!$O57:$U57-'7'!$O$60:$U$60))} -> 3 | F36: {=SUMPRODUCT(ABS('7'!$O57:$U57-'7'!$O$61:$U$61))} -> 3 | G36: {=SUMPRODUCT(ABS('7'!$O57:$U57-'7'!$O$62:$U$62))} -> 4 | H36: {=SUMPRODUCT(ABS('7'!$O57:$U57-'7'!$O$63:$U$63))} -> 3 | I36: {=SUMPRODUCT(ABS('7'!$O57:$U57-'7'!$O$64:$U$64))} -> 4 | J36: {=SUMPRODUCT(ABS('7'!$O57:$U57-'7'!$O$65:$U$65))} -> 3 | K36: {=SUMPRODUCT(ABS('7'!$O57:$U57-'7'!$O$66:$U$66))} -> 4 | L36: {=SUMPRODUCT(ABS('7'!$O57:$U57-'7'!$O$67:$U$67))} -> 3 | M36: {=SUMPRODUCT(ABS('7'!$O57:$U57-'7'!$O$68:$U$68))} -> 4 | N36: {=SUMPRODUCT(ABS('7'!$O57:$U57-'7'!$O$69:$U$69))} -> 4 | O36: {=SUMPRODUCT(ABS('7'!$O57:$U57-'7'!$O$70:$U$70))} -> 3 | P36: {=SUMPRODUCT(ABS('7'!$O57:$U57-'7'!$O$71:$U$71))} -> 4 | Q36: {=SUMPRODUCT(ABS('7'!$O57:$U57-'7'!$O$72:$U$72))} -> 7
A37: 1 | B37: {=SUMPRODUCT(ABS('7'!O58:U58-'7'!$O$57:$U$57))} -> 3 | C37: {=SUMPRODUCT(ABS('7'!$O58:$U58-'7'!$O$58:$U$58))} -> 0 | D37: {=SUMPRODUCT(ABS('7'!$O58:$U58-'7'!$O$59:$U$59))} -> 3 | E37: {=SUMPRODUCT(ABS('7'!$O58:$U58-'7'!$O$60:$U$60))} -> 4 | F37: {=SUMPRODUCT(ABS('7'!$O58:$U58-'7'!$O$61:$U$61))} -> 4 | G37: {=SUMPRODUCT(ABS('7'!$O58:$U58-'7'!$O$62:$U$62))} -> 3 | H37: {=SUMPRODUCT(ABS('7'!$O58:$U58-'7'!$O$63:$U$63))} -> 4 | I37: {=SUMPRODUCT(ABS('7'!$O58:$U58-'7'!$O$64:$U$64))} -> 3 | J37: {=SUMPRODUCT(ABS('7'!$O58:$U58-'7'!$O$65:$U$65))} -> 4 | K37: {=SUMPRODUCT(ABS('7'!$O58:$U58-'7'!$O$66:$U$66))} -> 3 | L37: {=SUMPRODUCT(ABS('7'!$O58:$U58-'7'!$O$67:$U$67))} -> 4 | M37: {=SUMPRODUCT(ABS('7'!$O58:$U58-'7'!$O$68:$U$68))} -> 3 | N37: {=SUMPRODUCT(ABS('7'!$O58:$U58-'7'!$O$69:$U$69))} -> 3 | O37: {=SUMPRODUCT(ABS('7'!$O58:$U58-'7'!$O$70:$U$70))} -> 4 | P37: {=SUMPRODUCT(ABS('7'!$O58:$U58-'7'!$O$71:$U$71))} -> 7 | Q37: {=SUMPRODUCT(ABS('7'!$O58:$U58-'7'!$O$72:$U$72))} -> 4
A38: 2 | B38: {=SUMPRODUCT(ABS('7'!O59:U59-'7'!$O$57:$U$57))} -> 4 | C38: {=SUMPRODUCT(ABS('7'!$O59:$U59-'7'!$O$58:$U$58))} -> 3 | D38: {=SUMPRODUCT(ABS('7'!$O59:$U59-'7'!$O$59:$U$59))} -> 0 | E38: {=SUMPRODUCT(ABS('7'!$O59:$U59-'7'!$O$60:$U$60))} -> 3 | F38: {=SUMPRODUCT(ABS('7'!$O59:$U59-'7'!$O$61:$U$61))} -> 3 | G38: {=SUMPRODUCT(ABS('7'!$O59:$U59-'7'!$O$62:$U$62))} -> 4 | H38: {=SUMPRODUCT(ABS('7'!$O59:$U59-'7'!$O$63:$U$63))} -> 3 | I38: {=SUMPRODUCT(ABS('7'!$O59:$U59-'7'!$O$64:$U$64))} -> 4 | J38: {=SUMPRODUCT(ABS('7'!$O59:$U59-'7'!$O$65:$U$65))} -> 3 | K38: {=SUMPRODUCT(ABS('7'!$O59:$U59-'7'!$O$66:$U$66))} -> 4 | L38: {=SUMPRODUCT(ABS('7'!$O59:$U59-'7'!$O$67:$U$67))} -> 3 | M38: {=SUMPRODUCT(ABS('7'!$O59:$U59-'7'!$O$68:$U$68))} -> 4 | N38: {=SUMPRODUCT(ABS('7'!$O59:$U59-'7'!$O$69:$U$69))} -> 4 | O38: {=SUMPRODUCT(ABS('7'!$O59:$U59-'7'!$O$70:$U$70))} -> 7 | P38: {=SUMPRODUCT(ABS('7'!$O59:$U59-'7'!$O$71:$U$71))} -> 4 | Q38: {=SUMPRODUCT(ABS('7'!$O59:$U59-'7'!$O$72:$U$72))} -> 3
A39: 3 | B39: {=SUMPRODUCT(ABS('7'!O60:U60-'7'!$O$57:$U$57))} -> 3 | C39: {=SUMPRODUCT(ABS('7'!$O60:$U60-'7'!$O$58:$U$58))} -> 4 | D39: {=SUMPRODUCT(ABS('7'!$O60:$U60-'7'!$O$59:$U$59))} -> 3 | E39: {=SUMPRODUCT(ABS('7'!$O60:$U60-'7'!$O$60:$U$60))} -> 0 | F39: {=SUMPRODUCT(ABS('7'!$O60:$U60-'7'!$O$61:$U$61))} -> 4 | G39: {=SUMPRODUCT(ABS('7'!$O60:$U60-'7'!$O$62:$U$62))} -> 3 | H39: {=SUMPRODUCT(ABS('7'!$O60:$U60-'7'!$O$63:$U$63))} -> 4 | I39: {=SUMPRODUCT(ABS('7'!$O60:$U60-'7'!$O$64:$U$64))} -> 3 | J39: {=SUMPRODUCT(ABS('7'!$O60:$U60-'7'!$O$65:$U$65))} -> 4 | K39: {=SUMPRODUCT(ABS('7'!$O60:$U60-'7'!$O$66:$U$66))} -> 3 | L39: {=SUMPRODUCT(ABS('7'!$O60:$U60-'7'!$O$67:$U$67))} -> 4 | M39: {=SUMPRODUCT(ABS('7'!$O60:$U60-'7'!$O$68:$U$68))} -> 3 | N39: {=SUMPRODUCT(ABS('7'!$O60:$U60-'7'!$O$69:$U$69))} -> 7 | O39: {=SUMPRODUCT(ABS('7'!$O60:$U60-'7'!$O$70:$U$70))} -> 4 | P39: {=SUMPRODUCT(ABS('7'!$O60:$U60-'7'!$O$71:$U$71))} -> 3 | Q39: {=SUMPRODUCT(ABS('7'!$O60:$U60-'7'!$O$72:$U$72))} -> 4
A40: 4 | B40: {=SUMPRODUCT(ABS('7'!O61:U61-'7'!$O$57:$U$57))} -> 3 | C40: {=SUMPRODUCT(ABS('7'!$O61:$U61-'7'!$O$58:$U$58))} -> 4 | D40: {=SUMPRODUCT(ABS('7'!$O61:$U61-'7'!$O$59:$U$59))} -> 3 | E40: {=SUMPRODUCT(ABS('7'!$O61:$U61-'7'!$O$60:$U$60))} -> 4 | F40: {=SUMPRODUCT(ABS('7'!$O61:$U61-'7'!$O$61:$U$61))} -> 0 | G40: {=SUMPRODUCT(ABS('7'!$O61:$U61-'7'!$O$62:$U$62))} -> 3 | H40: {=SUMPRODUCT(ABS('7'!$O61:$U61-'7'!$O$63:$U$63))} -> 4 | I40: {=SUMPRODUCT(ABS('7'!$O61:$U61-'7'!$O$64:$U$64))} -> 3 | J40: {=SUMPRODUCT(ABS('7'!$O61:$U61-'7'!$O$65:$U$65))} -> 4 | K40: {=SUMPRODUCT(ABS('7'!$O61:$U61-'7'!$O$66:$U$66))} -> 3 | L40: {=SUMPRODUCT(ABS('7'!$O61:$U61-'7'!$O$67:$U$67))} -> 4 | M40: {=SUMPRODUCT(ABS('7'!$O61:$U61-'7'!$O$68:$U$68))} -> 7 | N40: {=SUMPRODUCT(ABS('7'!$O61:$U61-'7'!$O$69:$U$69))} -> 3 | O40: {=SUMPRODUCT(ABS('7'!$O61:$U61-'7'!$O$70:$U$70))} -> 4 | P40: {=SUMPRODUCT(ABS('7'!$O61:$U61-'7'!$O$71:$U$71))} -> 3 | Q40: {=SUMPRODUCT(ABS('7'!$O61:$U61-'7'!$O$72:$U$72))} -> 4
A41: 5 | B41: {=SUMPRODUCT(ABS('7'!O62:U62-'7'!$O$57:$U$57))} -> 4 | C41: {=SUMPRODUCT(ABS('7'!$O62:$U62-'7'!$O$58:$U$58))} -> 3 | D41: {=SUMPRODUCT(ABS('7'!$O62:$U62-'7'!$O$59:$U$59))} -> 4 | E41: {=SUMPRODUCT(ABS('7'!$O62:$U62-'7'!$O$60:$U$60))} -> 3 | F41: {=SUMPRODUCT(ABS('7'!$O62:$U62-'7'!$O$61:$U$61))} -> 3 | G41: {=SUMPRODUCT(ABS('7'!$O62:$U62-'7'!$O$62:$U$62))} -> 0 | H41: {=SUMPRODUCT(ABS('7'!$O62:$U62-'7'!$O$63:$U$63))} -> 3 | I41: {=SUMPRODUCT(ABS('7'!$O62:$U62-'7'!$O$64:$U$64))} -> 4 | J41: {=SUMPRODUCT(ABS('7'!$O62:$U62-'7'!$O$65:$U$65))} -> 3 | K41: {=SUMPRODUCT(ABS('7'!$O62:$U62-'7'!$O$66:$U$66))} -> 4 | L41: {=SUMPRODUCT(ABS('7'!$O62:$U62-'7'!$O$67:$U$67))} -> 7 | M41: {=SUMPRODUCT(ABS('7'!$O62:$U62-'7'!$O$68:$U$68))} -> 4 | N41: {=SUMPRODUCT(ABS('7'!$O62:$U62-'7'!$O$69:$U$69))} -> 4 | O41: {=SUMPRODUCT(ABS('7'!$O62:$U62-'7'!$O$70:$U$70))} -> 3 | P41: {=SUMPRODUCT(ABS('7'!$O62:$U62-'7'!$O$71:$U$71))} -> 4 | Q41: {=SUMPRODUCT(ABS('7'!$O62:$U62-'7'!$O$72:$U$72))} -> 3
A42: 6 | B42: {=SUMPRODUCT(ABS('7'!O63:U63-'7'!$O$57:$U$57))} -> 3 | C42: {=SUMPRODUCT(ABS('7'!$O63:$U63-'7'!$O$58:$U$58))} -> 4 | D42: {=SUMPRODUCT(ABS('7'!$O63:$U63-'7'!$O$59:$U$59))} -> 3 | E42: {=SUMPRODUCT(ABS('7'!$O63:$U63-'7'!$O$60:$U$60))} -> 4 | F42: {=SUMPRODUCT(ABS('7'!$O63:$U63-'7'!$O$61:$U$61))} -> 4 | G42: {=SUMPRODUCT(ABS('7'!$O63:$U63-'7'!$O$62:$U$62))} -> 3 | H42: {=SUMPRODUCT(ABS('7'!$O63:$U63-'7'!$O$63:$U$63))} -> 0 | I42: {=SUMPRODUCT(ABS('7'!$O63:$U63-'7'!$O$64:$U$64))} -> 3 | J42: {=SUMPRODUCT(ABS('7'!$O63:$U63-'7'!$O$65:$U$65))} -> 4 | K42: {=SUMPRODUCT(ABS('7'!$O63:$U63-'7'!$O$66:$U$66))} -> 7 | L42: {=SUMPRODUCT(ABS('7'!$O63:$U63-'7'!$O$67:$U$67))} -> 4 | M42: {=SUMPRODUCT(ABS('7'!$O63:$U63-'7'!$O$68:$U$68))} -> 3 | N42: {=SUMPRODUCT(ABS('7'!$O63:$U63-'7'!$O$69:$U$69))} -> 3 | O42: {=SUMPRODUCT(ABS('7'!$O63:$U63-'7'!$O$70:$U$70))} -> 4 | P42: {=SUMPRODUCT(ABS('7'!$O63:$U63-'7'!$O$71:$U$71))} -> 3 | Q42: {=SUMPRODUCT(ABS('7'!$O63:$U63-'7'!$O$72:$U$72))} -> 4
A43: 7 | B43: {=SUMPRODUCT(ABS('7'!O64:U64-'7'!$O$57:$U$57))} -> 4 | C43: {=SUMPRODUCT(ABS('7'!$O64:$U64-'7'!$O$58:$U$58))} -> 3 | D43: {=SUMPRODUCT(ABS('7'!$O64:$U64-'7'!$O$59:$U$59))} -> 4 | E43: {=SUMPRODUCT(ABS('7'!$O64:$U64-'7'!$O$60:$U$60))} -> 3 | F43: {=SUMPRODUCT(ABS('7'!$O64:$U64-'7'!$O$61:$U$61))} -> 3 | G43: {=SUMPRODUCT(ABS('7'!$O64:$U64-'7'!$O$62:$U$62))} -> 4 | H43: {=SUMPRODUCT(ABS('7'!$O64:$U64-'7'!$O$63:$U$63))} -> 3 | I43: {=SUMPRODUCT(ABS('7'!$O64:$U64-'7'!$O$64:$U$64))} -> 0 | J43: {=SUMPRODUCT(ABS('7'!$O64:$U64-'7'!$O$65:$U$65))} -> 7 | K43: {=SUMPRODUCT(ABS('7'!$O64:$U64-'7'!$O$66:$U$66))} -> 4 | L43: {=SUMPRODUCT(ABS('7'!$O64:$U64-'7'!$O$67:$U$67))} -> 3 | M43: {=SUMPRODUCT(ABS('7'!$O64:$U64-'7'!$O$68:$U$68))} -> 4 | N43: {=SUMPRODUCT(ABS('7'!$O64:$U64-'7'!$O$69:$U$69))} -> 4 | O43: {=SUMPRODUCT(ABS('7'!$O64:$U64-'7'!$O$70:$U$70))} -> 3 | P43: {=SUMPRODUCT(ABS('7'!$O64:$U64-'7'!$O$71:$U$71))} -> 4 | Q43: {=SUMPRODUCT(ABS('7'!$O64:$U64-'7'!$O$72:$U$72))} -> 3
A44: 8 | B44: {=SUMPRODUCT(ABS('7'!O65:U65-'7'!$O$57:$U$57))} -> 3 | C44: {=SUMPRODUCT(ABS('7'!$O65:$U65-'7'!$O$58:$U$58))} -> 4 | D44: {=SUMPRODUCT(ABS('7'!$O65:$U65-'7'!$O$59:$U$59))} -> 3 | E44: {=SUMPRODUCT(ABS('7'!$O65:$U65-'7'!$O$60:$U$60))} -> 4 | F44: {=SUMPRODUCT(ABS('7'!$O65:$U65-'7'!$O$61:$U$61))} -> 4 | G44: {=SUMPRODUCT(ABS('7'!$O65:$U65-'7'!$O$62:$U$62))} -> 3 | H44: {=SUMPRODUCT(ABS('7'!$O65:$U65-'7'!$O$63:$U$63))} -> 4 | I44: {=SUMPRODUCT(ABS('7'!$O65:$U65-'7'!$O$64:$U$64))} -> 7 | J44: {=SUMPRODUCT(ABS('7'!$O65:$U65-'7'!$O$65:$U$65))} -> 0 | K44: {=SUMPRODUCT(ABS('7'!$O65:$U65-'7'!$O$66:$U$66))} -> 3 | L44: {=SUMPRODUCT(ABS('7'!$O65:$U65-'7'!$O$67:$U$67))} -> 4 | M44: {=SUMPRODUCT(ABS('7'!$O65:$U65-'7'!$O$68:$U$68))} -> 3 | N44: {=SUMPRODUCT(ABS('7'!$O65:$U65-'7'!$O$69:$U$69))} -> 3 | O44: {=SUMPRODUCT(ABS('7'!$O65:$U65-'7'!$O$70:$U$70))} -> 4 | P44: {=SUMPRODUCT(ABS('7'!$O65:$U65-'7'!$O$71:$U$71))} -> 3 | Q44: {=SUMPRODUCT(ABS('7'!$O65:$U65-'7'!$O$72:$U$72))} -> 4
A45: 9 | B45: {=SUMPRODUCT(ABS('7'!O66:U66-'7'!$O$57:$U$57))} -> 4 | C45: {=SUMPRODUCT(ABS('7'!$O66:$U66-'7'!$O$58:$U$58))} -> 3 | D45: {=SUMPRODUCT(ABS('7'!$O66:$U66-'7'!$O$59:$U$59))} -> 4 | E45: {=SUMPRODUCT(ABS('7'!$O66:$U66-'7'!$O$60:$U$60))} -> 3 | F45: {=SUMPRODUCT(ABS('7'!$O66:$U66-'7'!$O$61:$U$61))} -> 3 | G45: {=SUMPRODUCT(ABS('7'!$O66:$U66-'7'!$O$62:$U$62))} -> 4 | H45: {=SUMPRODUCT(ABS('7'!$O66:$U66-'7'!$O$63:$U$63))} -> 7 | I45: {=SUMPRODUCT(ABS('7'!$O66:$U66-'7'!$O$64:$U$64))} -> 4 | J45: {=SUMPRODUCT(ABS('7'!$O66:$U66-'7'!$O$65:$U$65))} -> 3 | K45: {=SUMPRODUCT(ABS('7'!$O66:$U66-'7'!$O$66:$U$66))} -> 0 | L45: {=SUMPRODUCT(ABS('7'!$O66:$U66-'7'!$O$67:$U$67))} -> 3 | M45: {=SUMPRODUCT(ABS('7'!$O66:$U66-'7'!$O$68:$U$68))} -> 4 | N45: {=SUMPRODUCT(ABS('7'!$O66:$U66-'7'!$O$69:$U$69))} -> 4 | O45: {=SUMPRODUCT(ABS('7'!$O66:$U66-'7'!$O$70:$U$70))} -> 3 | P45: {=SUMPRODUCT(ABS('7'!$O66:$U66-'7'!$O$71:$U$71))} -> 4 | Q45: {=SUMPRODUCT(ABS('7'!$O66:$U66-'7'!$O$72:$U$72))} -> 3
A46: 10 | B46: {=SUMPRODUCT(ABS('7'!O67:U67-'7'!$O$57:$U$57))} -> 3 | C46: {=SUMPRODUCT(ABS('7'!$O67:$U67-'7'!$O$58:$U$58))} -> 4 | D46: {=SUMPRODUCT(ABS('7'!$O67:$U67-'7'!$O$59:$U$59))} -> 3 | E46: {=SUMPRODUCT(ABS('7'!$O67:$U67-'7'!$O$60:$U$60))} -> 4 | F46: {=SUMPRODUCT(ABS('7'!$O67:$U67-'7'!$O$61:$U$61))} -> 4 | G46: {=SUMPRODUCT(ABS('7'!$O67:$U67-'7'!$O$62:$U$62))} -> 7 | H46: {=SUMPRODUCT(ABS('7'!$O67:$U67-'7'!$O$63:$U$63))} -> 4 | I46: {=SUMPRODUCT(ABS('7'!$O67:$U67-'7'!$O$64:$U$64))} -> 3 | J46: {=SUMPRODUCT(ABS('7'!$O67:$U67-'7'!$O$65:$U$65))} -> 4 | K46: {=SUMPRODUCT(ABS('7'!$O67:$U67-'7'!$O$66:$U$66))} -> 3 | L46: {=SUMPRODUCT(ABS('7'!$O67:$U67-'7'!$O$67:$U$67))} -> 0 | M46: {=SUMPRODUCT(ABS('7'!$O67:$U67-'7'!$O$68:$U$68))} -> 3 | N46: {=SUMPRODUCT(ABS('7'!$O67:$U67-'7'!$O$69:$U$69))} -> 3 | O46: {=SUMPRODUCT(ABS('7'!$O67:$U67-'7'!$O$70:$U$70))} -> 4 | P46: {=SUMPRODUCT(ABS('7'!$O67:$U67-'7'!$O$71:$U$71))} -> 3 | Q46: {=SUMPRODUCT(ABS('7'!$O67:$U67-'7'!$O$72:$U$72))} -> 4
...

Sheet 9
